ERROR 2018-10-16 19:42:52,740 exception 18792 13880 Internal Server Error: /blog/index/
Traceback (most recent call last):
  File "D:\work\web\lib\site-packages\django\core\handlers\exception.py", line 41, in inner
    response = get_response(request)
  File "D:\work\web\lib\site-packages\django\core\handlers\base.py", line 187, in _get_response
    response = self.process_exception_by_middleware(e, request)
  File "D:\work\web\lib\site-packages\django\core\handlers\base.py", line 185, in _get_response
    response = wrapped_callback(request, *callback_args, **callback_kwargs)
  File "D:\work\web\day03\demo01\blog\views.py", line 26, in index
    logger = looging.getLogger("django")
NameError: name 'looging' is not defined
ERROR 2018-10-16 19:42:58,909 basehttp 18792 13880 "GET /blog/index/ HTTP/1.1" 500 68289
WARNING 2018-10-16 19:43:40,750 views 18152 14544 首页运行
WARNING 2018-10-16 19:43:41,209 basehttp 18152 17508 "GET /static/uepload/static/blog/img/headers/4.jpg HTTP/1.1" 404 1724
WARNING 2018-10-16 19:43:41,211 basehttp 18152 7812 "GET /static/uepload/static/img/img/headers/5_lwKLNSr.jpg HTTP/1.1" 404 1745
WARNING 2018-10-16 19:43:41,267 basehttp 18152 6368 "GET /static/uepload/static/img/img/headers/25.jpg HTTP/1.1" 404 1724
WARNING 2018-10-16 19:43:41,289 basehttp 18152 12232 "GET /static/uepload/static/img/img/headers/%E5%9B%9B%E8%B0%8E.jpg HTTP/1.1" 404 1748
WARNING 2018-10-16 19:43:41,296 basehttp 18152 18492 "GET /static/uepload/static/img/img/headers/9_t9m1LMX.jpg HTTP/1.1" 404 1745
WARNING 2018-10-16 19:48:35,589 views 14012 15872 首页运行
WARNING 2018-10-16 19:48:35,688 basehttp 14012 10000 "GET /static/uepload/static/blog/img/headers/4.jpg HTTP/1.1" 404 1724
WARNING 2018-10-16 19:48:35,698 basehttp 14012 4160 "GET /static/uepload/static/img/img/headers/5_lwKLNSr.jpg HTTP/1.1" 404 1745
WARNING 2018-10-16 19:48:35,708 basehttp 14012 15132 "GET /static/uepload/static/img/img/headers/25.jpg HTTP/1.1" 404 1724
WARNING 2018-10-16 19:48:35,761 basehttp 14012 15072 "GET /static/uepload/static/img/img/headers/9_t9m1LMX.jpg HTTP/1.1" 404 1745
WARNING 2018-10-16 19:48:35,765 basehttp 14012 2380 "GET /static/uepload/static/img/img/headers/%E5%9B%9B%E8%B0%8E.jpg HTTP/1.1" 404 1748
WARNING 2018-10-16 19:48:35,806 basehttp 14012 9332 "GET /static/uepload/static/blog/img/headers/4.jpg HTTP/1.1" 404 1724
WARNING 2018-10-16 22:52:37,904 views 9092 8388 首页运行
ERROR 2018-10-16 22:52:38,007 exception 9092 8388 Internal Server Error: /
Traceback (most recent call last):
  File "D:\work\web\lib\site-packages\django\db\backends\utils.py", line 65, in execute
    return self.cursor.execute(sql, params)
  File "D:\work\web\lib\site-packages\django\db\backends\mysql\base.py", line 101, in execute
    return self.cursor.execute(query, args)
  File "D:\work\web\lib\site-packages\pymysql\cursors.py", line 170, in execute
    result = self._query(query)
  File "D:\work\web\lib\site-packages\pymysql\cursors.py", line 328, in _query
    conn.query(q)
  File "D:\work\web\lib\site-packages\pymysql\connections.py", line 516, in query
    self._affected_rows = self._read_query_result(unbuffered=unbuffered)
  File "D:\work\web\lib\site-packages\pymysql\connections.py", line 727, in _read_query_result
    result.read()
  File "D:\work\web\lib\site-packages\pymysql\connections.py", line 1066, in read
    first_packet = self.connection._read_packet()
  File "D:\work\web\lib\site-packages\pymysql\connections.py", line 683, in _read_packet
    packet.check_error()
  File "D:\work\web\lib\site-packages\pymysql\protocol.py", line 220, in check_error
    err.raise_mysql_exception(self._data)
  File "D:\work\web\lib\site-packages\pymysql\err.py", line 109, in raise_mysql_exception
    raise errorclass(errno, errval)
pymysql.err.InternalError: (1054, "Unknown column 'blog_article.remake' in 'field list'")

The above exception was the direct cause of the following exception:

Traceback (most recent call last):
  File "D:\work\web\lib\site-packages\django\core\handlers\exception.py", line 41, in inner
    response = get_response(request)
  File "D:\work\web\lib\site-packages\django\core\handlers\base.py", line 187, in _get_response
    response = self.process_exception_by_middleware(e, request)
  File "D:\work\web\lib\site-packages\django\core\handlers\base.py", line 185, in _get_response
    response = wrapped_callback(request, *callback_args, **callback_kwargs)
  File "D:\work\web\day03\demo01\blog\views.py", line 28, in index
    articles = cacheUtils.get_all_article()
  File "D:\work\web\day03\demo01\blog\cacheUtils.py", line 19, in get_all_article
    cache.set("allArticle", articles)
  File "D:\work\web\lib\site-packages\django_redis\cache.py", line 32, in _decorator
    return method(self, *args, **kwargs)
  File "D:\work\web\lib\site-packages\django_redis\cache.py", line 67, in set
    return self.client.set(*args, **kwargs)
  File "D:\work\web\lib\site-packages\django_redis\client\default.py", line 114, in set
    nvalue = self.encode(value)
  File "D:\work\web\lib\site-packages\django_redis\client\default.py", line 326, in encode
    value = self._serializer.dumps(value)
  File "D:\work\web\lib\site-packages\django_redis\serializers\pickle.py", line 32, in dumps
    return pickle.dumps(value, self._pickle_version)
  File "D:\work\web\lib\site-packages\django\db\models\query.py", line 202, in __getstate__
    self._fetch_all()
  File "D:\work\web\lib\site-packages\django\db\models\query.py", line 1102, in _fetch_all
    self._result_cache = list(self._iterable_class(self))
  File "D:\work\web\lib\site-packages\django\db\models\query.py", line 53, in __iter__
    results = compiler.execute_sql(chunked_fetch=self.chunked_fetch)
  File "D:\work\web\lib\site-packages\django\db\models\sql\compiler.py", line 876, in execute_sql
    cursor.execute(sql, params)
  File "D:\work\web\lib\site-packages\django\db\backends\utils.py", line 80, in execute
    return super(CursorDebugWrapper, self).execute(sql, params)
  File "D:\work\web\lib\site-packages\django\db\backends\utils.py", line 65, in execute
    return self.cursor.execute(sql, params)
  File "D:\work\web\lib\site-packages\django\db\utils.py", line 94, in __exit__
    six.reraise(dj_exc_type, dj_exc_value, traceback)
  File "D:\work\web\lib\site-packages\django\utils\six.py", line 685, in reraise
    raise value.with_traceback(tb)
  File "D:\work\web\lib\site-packages\django\db\backends\utils.py", line 65, in execute
    return self.cursor.execute(sql, params)
  File "D:\work\web\lib\site-packages\django\db\backends\mysql\base.py", line 101, in execute
    return self.cursor.execute(query, args)
  File "D:\work\web\lib\site-packages\pymysql\cursors.py", line 170, in execute
    result = self._query(query)
  File "D:\work\web\lib\site-packages\pymysql\cursors.py", line 328, in _query
    conn.query(q)
  File "D:\work\web\lib\site-packages\pymysql\connections.py", line 516, in query
    self._affected_rows = self._read_query_result(unbuffered=unbuffered)
  File "D:\work\web\lib\site-packages\pymysql\connections.py", line 727, in _read_query_result
    result.read()
  File "D:\work\web\lib\site-packages\pymysql\connections.py", line 1066, in read
    first_packet = self.connection._read_packet()
  File "D:\work\web\lib\site-packages\pymysql\connections.py", line 683, in _read_packet
    packet.check_error()
  File "D:\work\web\lib\site-packages\pymysql\protocol.py", line 220, in check_error
    err.raise_mysql_exception(self._data)
  File "D:\work\web\lib\site-packages\pymysql\err.py", line 109, in raise_mysql_exception
    raise errorclass(errno, errval)
django.db.utils.InternalError: (1054, "Unknown column 'blog_article.remake' in 'field list'")
ERROR 2018-10-16 22:52:43,572 basehttp 9092 8388 "GET / HTTP/1.1" 500 208464
WARNING 2018-10-16 22:52:44,619 base 9092 19180 Not Found: /favicon.ico
WARNING 2018-10-16 22:52:44,620 basehttp 9092 19180 "GET /favicon.ico HTTP/1.1" 404 2280
WARNING 2018-10-16 22:55:20,777 views 12916 5564 首页运行
ERROR 2018-10-16 22:55:20,801 exception 12916 5564 Internal Server Error: /
Traceback (most recent call last):
  File "D:\work\web\lib\site-packages\django\db\backends\utils.py", line 65, in execute
    return self.cursor.execute(sql, params)
  File "D:\work\web\lib\site-packages\django\db\backends\mysql\base.py", line 101, in execute
    return self.cursor.execute(query, args)
  File "D:\work\web\lib\site-packages\pymysql\cursors.py", line 170, in execute
    result = self._query(query)
  File "D:\work\web\lib\site-packages\pymysql\cursors.py", line 328, in _query
    conn.query(q)
  File "D:\work\web\lib\site-packages\pymysql\connections.py", line 516, in query
    self._affected_rows = self._read_query_result(unbuffered=unbuffered)
  File "D:\work\web\lib\site-packages\pymysql\connections.py", line 727, in _read_query_result
    result.read()
  File "D:\work\web\lib\site-packages\pymysql\connections.py", line 1066, in read
    first_packet = self.connection._read_packet()
  File "D:\work\web\lib\site-packages\pymysql\connections.py", line 683, in _read_packet
    packet.check_error()
  File "D:\work\web\lib\site-packages\pymysql\protocol.py", line 220, in check_error
    err.raise_mysql_exception(self._data)
  File "D:\work\web\lib\site-packages\pymysql\err.py", line 109, in raise_mysql_exception
    raise errorclass(errno, errval)
pymysql.err.InternalError: (1054, "Unknown column 'blog_article.remake' in 'field list'")

The above exception was the direct cause of the following exception:

Traceback (most recent call last):
  File "D:\work\web\lib\site-packages\django\core\handlers\exception.py", line 41, in inner
    response = get_response(request)
  File "D:\work\web\lib\site-packages\django\core\handlers\base.py", line 187, in _get_response
    response = self.process_exception_by_middleware(e, request)
  File "D:\work\web\lib\site-packages\django\core\handlers\base.py", line 185, in _get_response
    response = wrapped_callback(request, *callback_args, **callback_kwargs)
  File "D:\work\web\day03\demo01\blog\views.py", line 28, in index
    articles = cacheUtils.get_all_article()
  File "D:\work\web\day03\demo01\blog\cacheUtils.py", line 19, in get_all_article
    cache.set("allArticle", articles)
  File "D:\work\web\lib\site-packages\django_redis\cache.py", line 32, in _decorator
    return method(self, *args, **kwargs)
  File "D:\work\web\lib\site-packages\django_redis\cache.py", line 67, in set
    return self.client.set(*args, **kwargs)
  File "D:\work\web\lib\site-packages\django_redis\client\default.py", line 114, in set
    nvalue = self.encode(value)
  File "D:\work\web\lib\site-packages\django_redis\client\default.py", line 326, in encode
    value = self._serializer.dumps(value)
  File "D:\work\web\lib\site-packages\django_redis\serializers\pickle.py", line 32, in dumps
    return pickle.dumps(value, self._pickle_version)
  File "D:\work\web\lib\site-packages\django\db\models\query.py", line 202, in __getstate__
    self._fetch_all()
  File "D:\work\web\lib\site-packages\django\db\models\query.py", line 1102, in _fetch_all
    self._result_cache = list(self._iterable_class(self))
  File "D:\work\web\lib\site-packages\django\db\models\query.py", line 53, in __iter__
    results = compiler.execute_sql(chunked_fetch=self.chunked_fetch)
  File "D:\work\web\lib\site-packages\django\db\models\sql\compiler.py", line 876, in execute_sql
    cursor.execute(sql, params)
  File "D:\work\web\lib\site-packages\django\db\backends\utils.py", line 80, in execute
    return super(CursorDebugWrapper, self).execute(sql, params)
  File "D:\work\web\lib\site-packages\django\db\backends\utils.py", line 65, in execute
    return self.cursor.execute(sql, params)
  File "D:\work\web\lib\site-packages\django\db\utils.py", line 94, in __exit__
    six.reraise(dj_exc_type, dj_exc_value, traceback)
  File "D:\work\web\lib\site-packages\django\utils\six.py", line 685, in reraise
    raise value.with_traceback(tb)
  File "D:\work\web\lib\site-packages\django\db\backends\utils.py", line 65, in execute
    return self.cursor.execute(sql, params)
  File "D:\work\web\lib\site-packages\django\db\backends\mysql\base.py", line 101, in execute
    return self.cursor.execute(query, args)
  File "D:\work\web\lib\site-packages\pymysql\cursors.py", line 170, in execute
    result = self._query(query)
  File "D:\work\web\lib\site-packages\pymysql\cursors.py", line 328, in _query
    conn.query(q)
  File "D:\work\web\lib\site-packages\pymysql\connections.py", line 516, in query
    self._affected_rows = self._read_query_result(unbuffered=unbuffered)
  File "D:\work\web\lib\site-packages\pymysql\connections.py", line 727, in _read_query_result
    result.read()
  File "D:\work\web\lib\site-packages\pymysql\connections.py", line 1066, in read
    first_packet = self.connection._read_packet()
  File "D:\work\web\lib\site-packages\pymysql\connections.py", line 683, in _read_packet
    packet.check_error()
  File "D:\work\web\lib\site-packages\pymysql\protocol.py", line 220, in check_error
    err.raise_mysql_exception(self._data)
  File "D:\work\web\lib\site-packages\pymysql\err.py", line 109, in raise_mysql_exception
    raise errorclass(errno, errval)
django.db.utils.InternalError: (1054, "Unknown column 'blog_article.remake' in 'field list'")
ERROR 2018-10-16 22:55:23,412 basehttp 12916 5564 "GET / HTTP/1.1" 500 208601
WARNING 2018-10-17 08:24:30,469 views 7616 19180 首页运行
ERROR 2018-10-17 08:24:30,509 exception 7616 19180 Internal Server Error: /
Traceback (most recent call last):
  File "D:\work\web\lib\site-packages\django\db\backends\utils.py", line 65, in execute
    return self.cursor.execute(sql, params)
  File "D:\work\web\lib\site-packages\django\db\backends\mysql\base.py", line 101, in execute
    return self.cursor.execute(query, args)
  File "D:\work\web\lib\site-packages\pymysql\cursors.py", line 170, in execute
    result = self._query(query)
  File "D:\work\web\lib\site-packages\pymysql\cursors.py", line 328, in _query
    conn.query(q)
  File "D:\work\web\lib\site-packages\pymysql\connections.py", line 516, in query
    self._affected_rows = self._read_query_result(unbuffered=unbuffered)
  File "D:\work\web\lib\site-packages\pymysql\connections.py", line 727, in _read_query_result
    result.read()
  File "D:\work\web\lib\site-packages\pymysql\connections.py", line 1066, in read
    first_packet = self.connection._read_packet()
  File "D:\work\web\lib\site-packages\pymysql\connections.py", line 683, in _read_packet
    packet.check_error()
  File "D:\work\web\lib\site-packages\pymysql\protocol.py", line 220, in check_error
    err.raise_mysql_exception(self._data)
  File "D:\work\web\lib\site-packages\pymysql\err.py", line 109, in raise_mysql_exception
    raise errorclass(errno, errval)
pymysql.err.InternalError: (1054, "Unknown column 'blog_article.remake' in 'field list'")

The above exception was the direct cause of the following exception:

Traceback (most recent call last):
  File "D:\work\web\lib\site-packages\django\core\handlers\exception.py", line 41, in inner
    response = get_response(request)
  File "D:\work\web\lib\site-packages\django\core\handlers\base.py", line 187, in _get_response
    response = self.process_exception_by_middleware(e, request)
  File "D:\work\web\lib\site-packages\django\core\handlers\base.py", line 185, in _get_response
    response = wrapped_callback(request, *callback_args, **callback_kwargs)
  File "D:\work\web\day03\demo01\blog\views.py", line 28, in index
    articles = cacheUtils.get_all_article()
  File "D:\work\web\day03\demo01\blog\cacheUtils.py", line 19, in get_all_article
    cache.set("allArticle", articles)
  File "D:\work\web\lib\site-packages\django_redis\cache.py", line 32, in _decorator
    return method(self, *args, **kwargs)
  File "D:\work\web\lib\site-packages\django_redis\cache.py", line 67, in set
    return self.client.set(*args, **kwargs)
  File "D:\work\web\lib\site-packages\django_redis\client\default.py", line 114, in set
    nvalue = self.encode(value)
  File "D:\work\web\lib\site-packages\django_redis\client\default.py", line 326, in encode
    value = self._serializer.dumps(value)
  File "D:\work\web\lib\site-packages\django_redis\serializers\pickle.py", line 32, in dumps
    return pickle.dumps(value, self._pickle_version)
  File "D:\work\web\lib\site-packages\django\db\models\query.py", line 202, in __getstate__
    self._fetch_all()
  File "D:\work\web\lib\site-packages\django\db\models\query.py", line 1102, in _fetch_all
    self._result_cache = list(self._iterable_class(self))
  File "D:\work\web\lib\site-packages\django\db\models\query.py", line 53, in __iter__
    results = compiler.execute_sql(chunked_fetch=self.chunked_fetch)
  File "D:\work\web\lib\site-packages\django\db\models\sql\compiler.py", line 876, in execute_sql
    cursor.execute(sql, params)
  File "D:\work\web\lib\site-packages\django\db\backends\utils.py", line 80, in execute
    return super(CursorDebugWrapper, self).execute(sql, params)
  File "D:\work\web\lib\site-packages\django\db\backends\utils.py", line 65, in execute
    return self.cursor.execute(sql, params)
  File "D:\work\web\lib\site-packages\django\db\utils.py", line 94, in __exit__
    six.reraise(dj_exc_type, dj_exc_value, traceback)
  File "D:\work\web\lib\site-packages\django\utils\six.py", line 685, in reraise
    raise value.with_traceback(tb)
  File "D:\work\web\lib\site-packages\django\db\backends\utils.py", line 65, in execute
    return self.cursor.execute(sql, params)
  File "D:\work\web\lib\site-packages\django\db\backends\mysql\base.py", line 101, in execute
    return self.cursor.execute(query, args)
  File "D:\work\web\lib\site-packages\pymysql\cursors.py", line 170, in execute
    result = self._query(query)
  File "D:\work\web\lib\site-packages\pymysql\cursors.py", line 328, in _query
    conn.query(q)
  File "D:\work\web\lib\site-packages\pymysql\connections.py", line 516, in query
    self._affected_rows = self._read_query_result(unbuffered=unbuffered)
  File "D:\work\web\lib\site-packages\pymysql\connections.py", line 727, in _read_query_result
    result.read()
  File "D:\work\web\lib\site-packages\pymysql\connections.py", line 1066, in read
    first_packet = self.connection._read_packet()
  File "D:\work\web\lib\site-packages\pymysql\connections.py", line 683, in _read_packet
    packet.check_error()
  File "D:\work\web\lib\site-packages\pymysql\protocol.py", line 220, in check_error
    err.raise_mysql_exception(self._data)
  File "D:\work\web\lib\site-packages\pymysql\err.py", line 109, in raise_mysql_exception
    raise errorclass(errno, errval)
django.db.utils.InternalError: (1054, "Unknown column 'blog_article.remake' in 'field list'")
ERROR 2018-10-17 08:24:33,204 basehttp 7616 19180 "GET / HTTP/1.1" 500 208463
WARNING 2018-10-17 08:27:59,251 views 22152 20572 首页运行
WARNING 2018-10-17 08:28:00,244 basehttp 22152 19440 "GET /static/uepload/static/blog/img/headers/4.jpg HTTP/1.1" 404 1724
WARNING 2018-10-17 08:28:00,267 basehttp 22152 4104 "GET /static/uepload/static/img/img/headers/5_lwKLNSr.jpg HTTP/1.1" 404 1745
WARNING 2018-10-17 08:28:00,276 basehttp 22152 22040 "GET /static/uepload/static/img/img/headers/25.jpg HTTP/1.1" 404 1724
WARNING 2018-10-17 08:28:00,348 basehttp 22152 13332 "GET /static/uepload/static/img/img/headers/%E5%9B%9B%E8%B0%8E.jpg HTTP/1.1" 404 1748
WARNING 2018-10-17 08:28:00,360 basehttp 22152 22472 "GET /static/uepload/static/img/img/headers/9_t9m1LMX.jpg HTTP/1.1" 404 1745
WARNING 2018-10-17 08:59:14,291 views 18052 15476 首页运行
WARNING 2018-10-17 08:59:14,684 basehttp 18052 15508 "GET /static/uepload/static/blog/img/headers/4.jpg HTTP/1.1" 404 1724
WARNING 2018-10-17 08:59:14,730 basehttp 18052 16776 "GET /static/uepload/static/img/img/headers/5_lwKLNSr.jpg HTTP/1.1" 404 1745
WARNING 2018-10-17 08:59:14,808 basehttp 18052 21776 "GET /static/uepload/static/img/img/headers/25.jpg HTTP/1.1" 404 1724
WARNING 2018-10-17 08:59:15,024 basehttp 18052 21516 "GET /static/uepload/static/img/img/headers/%E5%9B%9B%E8%B0%8E.jpg HTTP/1.1" 404 1748
WARNING 2018-10-17 08:59:15,069 basehttp 18052 2692 "GET /static/uepload/static/img/img/headers/9_t9m1LMX.jpg HTTP/1.1" 404 1745
WARNING 2018-10-17 08:59:15,091 basehttp 18052 20960 "GET /static/uepload/static/blog/img/headers/4.jpg HTTP/1.1" 404 1724
